Workbook
Name Donnees: Tableau1[]
Name Segment_Mois: #N/A
Name Segment_Projet_ou_client: #N/A

Sheet Données
A1: Décompte horaire | B1: Florence Louazel
A4: Période
A16: Projet ou client | B16: Date de début | C16: Mois | D16: Début | E16: Fin | F16: Durée | G16: Durée (heures et minutes) | H16: Tarif horaire | I16: Remboursements | J16: Remarques | K16: Payé / Non payé | L16: Gains | M16: Pause | N16: Autres revenus | O16: Taxes | P16: Type
A17: Création Entreprise | B17: 45868.356 | C17: =Tableau1[[#This Row],[Date de début]] -> 45868.356 | D17: 45868.356 | E17: 45868.383 | F17: 0.4 | G17: 24m | H17: 0 | I17: 0 | K17: Non payé | L17: 0 | P17: =IF(OR(Tableau1[[#This Row],[Projet ou client]]="Léane",Tableau1[[#This Row],[Projet ou client]]="Valentine",Tableau1[[#This Row],[Projet ou client]]="Léon",Tableau1[[#This Row],[Projet ou client]]="Camille"),"Cours particuliers","Autre") -> Autre
A18: Préparation ECAM | B18: 45868.384 | C18: =Tableau1[[#This Row],[Date de début]] -> 45868.384 | D18: 45868.384 | E18: 45868.444 | F18: 0.9 | G18: 54m | H18: 0 | I18: 0 | K18: Non payé | L18: 0 | P18: =IF(OR(Tableau1[[#This Row],[Projet ou client]]="Léane",Tableau1[[#This Row],[Projet ou client]]="Valentine",Tableau1[[#This Row],[Projet ou client]]="Léon",Tableau1[[#This Row],[Projet ou client]]="Camille"),"Cours particuliers","Autre") -> Autre
A19: Administratif | B19: 45868.422 | C19: =Tableau1[[#This Row],[Date de début]] -> 45868.422 | D19: 45868.422 | E19: 45868.443 | F19: 0.517 | G19: 31m | H19: 0 | I19: 0 | K19: Non payé | L19: 0 | P19: =IF(OR(Tableau1[[#This Row],[Projet ou client]]="Léane",Tableau1[[#This Row],[Projet ou client]]="Valentine",Tableau1[[#This Row],[Projet ou client]]="Léon",Tableau1[[#This Row],[Projet ou client]]="Camille"),"Cours particuliers","Autre") -> Autre
A20: Préparation ECAM | B20: 45868.445 | C20: =Tableau1[[#This Row],[Date de début]] -> 45868.445 | D20: 45868.445 | E20: 45868.467 | F20: 0.517 | G20: 31m | H20: 0 | I20: 0 | K20: Non payé | L20: 0 | P20: =IF(OR(Tableau1[[#This Row],[Projet ou client]]="Léane",Tableau1[[#This Row],[Projet ou client]]="Valentine",Tableau1[[#This Row],[Projet ou client]]="Léon",Tableau1[[#This Row],[Projet ou client]]="Camille"),"Cours particuliers","Autre") -> Autre
A21: Administratif | B21: 45868.467 | C21: =Tableau1[[#This Row],[Date de début]] -> 45868.467 | D21: 45868.467 | E21: 45868.485 | F21: 0.45 | G21: 27m | H21: 0 | I21: 0 | K21: Non payé | L21: 0 | P21: =IF(OR(Tableau1[[#This Row],[Projet ou client]]="Léane",Tableau1[[#This Row],[Projet ou client]]="Valentine",Tableau1[[#This Row],[Projet ou client]]="Léon",Tableau1[[#This Row],[Projet ou client]]="Camille"),"Cours particuliers","Autre") -> Autre
A22: Gestion Patrimoine | B22: 45868.535 | C22: =Tableau1[[#This Row],[Date de début]] -> 45868.535 | D22: 45868.535 | E22: 45868.58 | F22: 1.067 | G22: 1h 4min | H22: 0 | I22: 0 | K22: Non payé | L22: 0 | P22: =IF(OR(Tableau1[[#This Row],[Projet ou client]]="Léane",Tableau1[[#This Row],[Projet ou client]]="Valentine",Tableau1[[#This Row],[Projet ou client]]="Léon",Tableau1[[#This Row],[Projet ou client]]="Camille"),"Cours particuliers","Autre") -> Autre
A23: Administratif | B23: 45868.584 | C23: =Tableau1[[#This Row],[Date de début]] -> 45868.584 | D23: 45868.584 | E23: 45868.597 | F23: 0.317 | G23: 19m | H23: 0 | I23: 0 | K23: Non payé | L23: 0 | P23: =IF(OR(Tableau1[[#This Row],[Projet ou client]]="Léane",Tableau1[[#This Row],[Projet ou client]]="Valentine",Tableau1[[#This Row],[Projet ou client]]="Léon",Tableau1[[#This Row],[Projet ou client]]="Camille"),"Cours particuliers","Autre") -> Autre
A24: Préparation ISEN Maths | B24: 45868.597 | C24: =Tableau1[[#This Row],[Date de début]] -> 45868.597 | D24: 45868.597 | E24: 45868.647 | F24: 1.2 | G24: 1h 12min | H24: 0 | I24: 0 | K24: Non payé | L24: 0 | P24: =IF(OR(Tableau1[[#This Row],[Projet ou client]]="Léane",Tableau1[[#This Row],[Projet ou client]]="Valentine",Tableau1[[#This Row],[Projet ou client]]="Léon",Tableau1[[#This Row],[Projet ou client]]="Camille"),"Cours particuliers","Autre") -> Autre
A25: Préparation ISEN Maths | B25: 45868.675 | C25: =Tableau1[[#This Row],[Date de début]] -> 45868.675 | D25: 45868.675 | E25: 45868.722 | F25: 1.133 | G25: 1h 8min | H25: 0 | I25: 0 | K25: Non payé | L25: 0 | P25: =IF(OR(Tableau1[[#This Row],[Projet ou client]]="Léane",Tableau1[[#This Row],[Projet ou client]]="Valentine",Tableau1[[#This Row],[Projet ou client]]="Léon",Tableau1[[#This Row],[Projet ou client]]="Camille"),"Cours particuliers","Autre") -> Autre
A26: Administratif | B26: 45869.428 | C26: =Tableau1[[#This Row],[Date de début]] -> 45869.428 | D26: 45869.428 | E26: 45869.431 | F26: 0.083 | G26: 5m | H26: 0 | I26: 0 | K26: Non payé | L26: 0 | P26: =IF(OR(Tableau1[[#This Row],[Projet ou client]]="Léane",Tableau1[[#This Row],[Projet ou client]]="Valentine",Tableau1[[#This Row],[Projet ou client]]="Léon",Tableau1[[#This Row],[Projet ou client]]="Camille"),"Cours particuliers","Autre") -> Autre
A27: Préparation ECAM | B27: 45869.431 | C27: =Tableau1[[#This Row],[Date de début]] -> 45869.431 | D27: 45869.431 | E27: 45869.535 | F27: 2.483 | G27: 2h 29min | H27: 0 | I27: 0 | K27: Non payé | L27: 0 | P27: =IF(OR(Tableau1[[#This Row],[Projet ou client]]="Léane",Tableau1[[#This Row],[Projet ou client]]="Valentine",Tableau1[[#This Row],[Projet ou client]]="Léon",Tableau1[[#This Row],[Projet ou client]]="Camille"),"Cours particuliers","Autre") -> Autre
A28: Préparation ECAM | B28: 45869.601 | C28: =Tableau1[[#This Row],[Date de début]] -> 45869.601 | D28: 45869.601 | E28: 45869.653 | F28: 1.25 | G28: 1h 15min | H28: 0 | I28: 0 | K28: Non payé | L28: 0 | P28: =IF(OR(Tableau1[[#This Row],[Projet ou client]]="Léane",Tableau1[[#This Row],[Projet ou client]]="Valentine",Tableau1[[#This Row],[Projet ou client]]="Léon",Tableau1[[#This Row],[Projet ou client]]="Camille"),"Cours particuliers","Autre") -> Autre
... A44: Préparation ISEN Rhétorique | B44: 45891.492 | C44: =Tableau1[[#This Row],[Date de début]] -> 45891.492 | D44: 45891.492 | E44: 45891.506 | F44: 0.317 | G44: 19m | H44: 0 | I44: 0 | K44: Non payé | L44: 0 | P44: =IF(OR(Tableau1[[#This Row],[Projet ou client]]="Léane",Tableau1[[#This Row],[Projet ou client]]="Valentine",Tableau1[[#This Row],[Projet ou client]]="Léon",Tableau1[[#This Row],[Projet ou client]]="Camille"),"Cours particuliers","Autre") -> Autre
A45: Préparation Cours/Échanges Parents | B45: 45891.608 | C45: =Tableau1[[#This Row],[Date de début]] -> 45891.608 | D45: 45891.608 | E45: 45891.622 | F45: 0.35 | G45: 21m | H45: 0 | I45: 0 | J45: Appel Sophie | K45: Non payé | L45: 0 | P45: =IF(OR(Tableau1[[#This Row],[Projet ou client]]="Léane",Tableau1[[#This Row],[Projet ou client]]="Valentine",Tableau1[[#This Row],[Projet ou client]]="Léon",Tableau1[[#This Row],[Projet ou client]]="Camille"),"Cours particuliers","Autre") -> Autre
A46: Prospection | B46: 45891.622 | C46: =Tableau1[[#This Row],[Date de début]] -> 45891.622 | D46: 45891.622 | E46: 45891.626 | F46: 0.083 | G46: 5m | H46: 0 | I46: 0 | K46: Non payé | L46: 0 | P46: =IF(OR(Tableau1[[#This Row],[Projet ou client]]="Léane",Tableau1[[#This Row],[Projet ou client]]="Valentine",Tableau1[[#This Row],[Projet ou client]]="Léon",Tableau1[[#This Row],[Projet ou client]]="Camille"),"Cours particuliers","Autre") -> Autre
A47: Administratif | B47: 45891.626 | C47: =Tableau1[[#This Row],[Date de début]] -> 45891.626 | D47: 45891.626 | E47: 45891.631 | F47: 0.1 | G47: 6m | H47: 0 | I47: 0 | K47: Non payé | L47: 0 | P47: =IF(OR(Tableau1[[#This Row],[Projet ou client]]="Léane",Tableau1[[#This Row],[Projet ou client]]="Valentine",Tableau1[[#This Row],[Projet ou client]]="Léon",Tableau1[[#This Row],[Projet ou client]]="Camille"),"Cours particuliers","Autre") -> Autre
A48: Préparation ECAM | B48: 45891.63 | C48: =Tableau1[[#This Row],[Date de début]] -> 45891.63 | D48: 45891.63 | E48: 45891.782 | F48: 3.267 | G48: 3h 16min | H48: 0 | I48: 0 | K48: Non payé | L48: 0 | P48: =IF(OR(Tableau1[[#This Row],[Projet ou client]]="Léane",Tableau1[[#This Row],[Projet ou client]]="Valentine",Tableau1[[#This Row],[Projet ou client]]="Léon",Tableau1[[#This Row],[Projet ou client]]="Camille"),"Cours particuliers","Autre") -> Autre
A49: Administratif | B49: 45894.342 | C49: =Tableau1[[#This Row],[Date de début]] -> 45894.342 | D49: 45894.342 | E49: 45894.401 | F49: 1.417 | G49: 1h 25min | H49: 0 | I49: 0 | K49: Non payé | L49: 0 | P49: =IF(OR(Tableau1[[#This Row],[Projet ou client]]="Léane",Tableau1[[#This Row],[Projet ou client]]="Valentine",Tableau1[[#This Row],[Projet ou client]]="Léon",Tableau1[[#This Row],[Projet ou client]]="Camille"),"Cours particuliers","Autre") -> Autre
A50: Préparation ECAM | B50: 45894.401 | C50: =Tableau1[[#This Row],[Date de début]] -> 45894.401 | D50: 45894.401 | E50: 45894.498 | F50: 2.2 | G50: 2h 12min | H50: 0 | I50: 0 | K50: Non payé | L50: 0 | P50: =IF(OR(Tableau1[[#This Row],[Projet ou client]]="Léane",Tableau1[[#This Row],[Projet ou client]]="Valentine",Tableau1[[#This Row],[Projet ou client]]="Léon",Tableau1[[#This Row],[Projet ou client]]="Camille"),"Cours particuliers","Autre") -> Autre
A51: Préparation ISEN Maths | B51: 45894.541 | C51: =Tableau1[[#This Row],[Date de début]] -> 45894.541 | D51: 45894.541 | E51: 45894.624 | F51: 1.9 | G51: 1h 54min | H51: 0 | I51: 0 | K51: Non payé | L51: 0 | P51: =IF(OR(Tableau1[[#This Row],[Projet ou client]]="Léane",Tableau1[[#This Row],[Projet ou client]]="Valentine",Tableau1[[#This Row],[Projet ou client]]="Léon",Tableau1[[#This Row],[Projet ou client]]="Camille"),"Cours particuliers","Autre") -> Autre
A52: Création Entreprise | B52: 45894.719 | C52: =Tableau1[[#This Row],[Date de début]] -> 45894.719 | D52: 45894.719 | E52: 45894.744 | F52: 0.6 | G52: 36m | H52: 0 | I52: 0 | J52: NDA et exonération TVA | K52: Non payé | L52: 0 | P52: =IF(OR(Tableau1[[#This Row],[Projet ou client]]="Léane",Tableau1[[#This Row],[Projet ou client]]="Valentine",Tableau1[[#This Row],[Projet ou client]]="Léon",Tableau1[[#This Row],[Projet ou client]]="Camille"),"Cours particuliers","Autre") -> Autre
A53: Préparation ISEN Maths | B53: 45895.363 | C53: =Tableau1[[#This Row],[Date de début]] -> 45895.363 | D53: 45895.363 | E53: 45895.504 | F53: 3.083 | G53: 3h 5min | H53: 0 | I53: 0 | J53: Fin cours complexes | K53: Non payé | L53: 0 | P53: =IF(OR(Tableau1[[#This Row],[Projet ou client]]="Léane",Tableau1[[#This Row],[Projet ou client]]="Valentine",Tableau1[[#This Row],[Projet ou client]]="Léon",Tableau1[[#This Row],[Projet ou client]]="Camille"),"Cours particuliers","Autre") -> Autre
A54: Administratif | B54: 45895.572 | C54: =Tableau1[[#This Row],[Date de début]] -> 45895.572 | D54: 45895.572 | E54: 45895.583 | F54: 0.25 | G54: 15m | H54: 0 | I54: 0 | K54: Non payé | L54: 0 | P54: =IF(OR(Tableau1[[#This Row],[Projet ou client]]="Léane",Tableau1[[#This Row],[Projet ou client]]="Valentine",Tableau1[[#This Row],[Projet ou client]]="Léon",Tableau1[[#This Row],[Projet ou client]]="Camille"),"Cours particuliers","Autre") -> Autre
A55: Préparation ISEN Rhétorique | B55: 45895.583 | C55: =Tableau1[[#This Row],[Date de début]] -> 45895.583 | D55: 45895.583 | E55: 45895.644 | F55: 1.467 | G55: 1h 28min | H55: 0 | I55: 0 | K55: Non payé | L55: 0 | P55: =IF(OR(Tableau1[[#This Row],[Projet ou client]]="Léane",Tableau1[[#This Row],[Projet ou client]]="Valentine",Tableau1[[#This Row],[Projet ou client]]="Léon",Tableau1[[#This Row],[Projet ou client]]="Camille"),"Cours particuliers","Autre") -> Autre
A56: Création Entreprise | B56: 45896.387 | C56: =Tableau1[[#This Row],[Date de début]] -> 45896.387 | D56: 45896.387 | E56: 45896.417 | F56: 0.717 | G56: 43m | H56: 0 | I56: 0 | K56: Non payé | L56: 0 | P56: =IF(OR(Tableau1[[#This Row],[Projet ou client]]="Léane",Tableau1[[#This Row],[Projet ou client]]="Valentine",Tableau1[[#This Row],[Projet ou client]]="Léon",Tableau1[[#This Row],[Projet ou client]]="Camille"),"Cours particuliers","Autre") -> Autre
A57: Préparation ISEN Rhétorique | B57: 45896.437 | C57: =Tableau1[[#This Row],[Date de début]] -> 45896.437 | D57: 45896.437 | E57: 45896.507 | F57: 1.683 | G57: 1h 41min | H57: 0 | I57: 0 | K57: Non payé | L57: 0 | P57: =IF(OR(Tableau1[[#This Row],[Projet ou client]]="Léane",Tableau1[[#This Row],[Projet ou client]]="Valentine",Tableau1[[#This Row],[Projet ou client]]="Léon",Tableau1[[#This Row],[Projet ou client]]="Camille"),"Cours particuliers","Autre") -> Autre
A58: Planification/administratif ISEN | B58: 45896.507 | C58: =Tableau1[[#This Row],[Date de début]] -> 45896.507 | D58: 45896.507 | E58: 45896.535 | F58: 0.683 | G58: 41m | H58: 0 | I58: 0 | K58: Non payé | L58: 0 | P58: =IF(OR(Tableau1[[#This Row],[Projet ou client]]="Léane",Tableau1[[#This Row],[Projet ou client]]="Valentine",Tableau1[[#This Row],[Projet ou client]]="Léon",Tableau1[[#This Row],[Projet ou client]]="Camille"),"Cours particuliers","Autre") -> Autre
A59: Préparation Cours/Échanges Parents | B59: 45896.576 | C59: =Tableau1[[#This Row],[Date de début]] -> 45896.576 | D59: 45896.576 | E59: 45896.585 | F59: 0.217 | G59: 13m | H59: 0 | I59: 0 | K59: Non payé | L59: 0 | P59: =IF(OR(Tableau1[[#This Row],[Projet ou client]]="Léane",Tableau1[[#This Row],[Projet ou client]]="Valentine",Tableau1[[#This Row],[Projet ou client]]="Léon",Tableau1[[#This Row],[Projet ou client]]="Camille"),"Cours particuliers","Autre") -> Autre
A60: Léon | B60: 45896.607 | C60: =Tableau1[[#This Row],[Date de début]] -> 45896.607 | D60: 45896.607 | E60: 45896.669 | F60: 1.483 | G60: 1h 29min | H60: 40 | I60: 0 | K60: Non payé | L60: 59.32 | P60: =IF(OR(Tableau1[[#This Row],[Projet ou client]]="Léane",Tableau1[[#This Row],[Projet ou client]]="Valentine",Tableau1[[#This Row],[Projet ou client]]="Léon",Tableau1[[#This Row],[Projet ou client]]="Camille"),"Cours particuliers","Autre") -> Cours particuliers
A61: Administratif | B61: 45897.392 | C61: =Tableau1[[#This Row],[Date de début]] -> 45897.392 | D61: 45897.392 | E61: 45897.438 | F61: 1.033 | G61: 1h 2min | H61: 0 | I61: 0 | K61: Non payé | L61: 0 | P61: =IF(OR(Tableau1[[#This Row],[Projet ou client]]="Léane",Tableau1[[#This Row],[Projet ou client]]="Valentine",Tableau1[[#This Row],[Projet ou client]]="Léon",Tableau1[[#This Row],[Projet ou client]]="Camille"),"Cours particuliers","Autre") -> Autre
A62: Prospection | B62: 45897.438 | C62: =Tableau1[[#This Row],[Date de début]] -> 45897.438 | D62: 45897.438 | E62: 45897.456 | F62: 0.433 | G62: 26m | H62: 0 | I62: 0 | K62: Non payé | L62: 0 | P62: =IF(OR(Tableau1[[#This Row],[Projet ou client]]="Léane",Tableau1[[#This Row],[Projet ou client]]="Valentine",Tableau1[[#This Row],[Projet ou client]]="Léon",Tableau1[[#This Row],[Projet ou client]]="Camille"),"Cours particuliers","Autre") -> Autre
A63: RDV Client | B63: 45897.458 | C63: =Tableau1[[#This Row],[Date de début]] -> 45897.458 | D63: 45897.458 | E63: 45897.495 | F63: 0.883 | G63: 53m | H63: 0 | I63: 0 | J63: St Félix | K63: Non payé | L63: 0 | P63: =IF(OR(Tableau1[[#This Row],[Projet ou client]]="Léane",Tableau1[[#This Row],[Projet ou client]]="Valentine",Tableau1[[#This Row],[Projet ou client]]="Léon",Tableau1[[#This Row],[Projet ou client]]="Camille"),"Cours particuliers","Autre") -> Autre
A64: Prospection | B64: 45897.495 | C64: =Tableau1[[#This Row],[Date de début]] -> 45897.495 | D64: 45897.495 | E64: 45897.502 | F64: 0.167 | G64: 10m | H64: 0 | I64: 0 | K64: Non payé | L64: 0 | P64: =IF(OR(Tableau1[[#This Row],[Projet ou client]]="Léane",Tableau1[[#This Row],[Projet ou client]]="Valentine",Tableau1[[#This Row],[Projet ou client]]="Léon",Tableau1[[#This Row],[Projet ou client]]="Camille"),"Cours particuliers","Autre") -> Autre
A65: Organisation | B65: 45897.503 | C65: =Tableau1[[#This Row],[Date de début]] -> 45897.503 | D65: 45897.503 | E65: 45897.524 | F65: 0.5 | G65: 30m | H65: 0 | I65: 0 | K65: Non payé | L65: 0 | P65: =IF(OR(Tableau1[[#This Row],[Projet ou client]]="Léane",Tableau1[[#This Row],[Projet ou client]]="Valentine",Tableau1[[#This Row],[Projet ou client]]="Léon",Tableau1[[#This Row],[Projet ou client]]="Camille"),"Cours particuliers","Autre") -> Autre
A66: Gestion Patrimoine | B66: 45897.593 | C66: =Tableau1[[#This Row],[Date de début]] -> 45897.593 | D66: 45897.593 | E66: 45897.599 | F66: 0.15 | G66: 9m | H66: 0 | I66: 0 | K66: Non payé | L66: 0 | P66: =IF(OR(Tableau1[[#This Row],[Projet ou client]]="Léane",Tableau1[[#This Row],[Projet ou client]]="Valentine",Tableau1[[#This Row],[Projet ou client]]="Léon",Tableau1[[#This Row],[Projet ou client]]="Camille"),"Cours particuliers","Autre") -> Autre
A67: Préparation ISEN Maths | B67: 45897.6 | C67: =Tableau1[[#This Row],[Date de début]] -> 45897.6 | D67: 45897.6 | E67: 45897.679 | F67: 1.833 | G67: 1h 50min | H67: 0 | I67: 0 | J67: Début prep calculs algébriques | K67: Non payé | L67: 0 | P67: =IF(OR(Tableau1[[#This Row],[Projet ou client]]="Léane",Tableau1[[#This Row],[Projet ou client]]="Valentine",Tableau1[[#This Row],[Projet ou client]]="Léon",Tableau1[[#This Row],[Projet ou client]]="Camille"),"Cours particuliers","Autre") -> Autre
A68: Administratif | B68: 45897.692 | C68: =Tableau1[[#This Row],[Date de début]] -> 45897.692 | D68: 45897.692 | E68: 45897.703 | F68: 0.283 | G68: 17m | H68: 0 | I68: 0 | K68: Non payé | L68: 0 | P68: =IF(OR(Tableau1[[#This Row],[Projet ou client]]="Léane",Tableau1[[#This Row],[Projet ou client]]="Valentine",Tableau1[[#This Row],[Projet ou client]]="Léon",Tableau1[[#This Row],[Projet ou client]]="Camille"),"Cours particuliers","Autre") -> Autre
...

Sheet TCD
A1: Type | B1: Cours particuliers
A2: Mois | B2: (Plusieurs éléments)
G3: =GETPIVOTDATA(B3,B3,A7,GETPIVOTDATA("Somme de Durée",$A$3,"Projet ou client","Louis","Mois (Date de début)",12,"Trimestres (Date de début)",4,"Années (Date de début)",2024)) -> #REF!
A4: Étiquettes de lignes | B4: Somme de Durée | C4: Somme de Remboursements | D4: Somme de Gains
A5: Camille | B5: 3.566 | C5: 0 | D5: 124.81
A6: Valentine | B6: 1.65 | C6: 0 | D6: 66
A7: Léon | B7: 3.317 | C7: 0 | D7: 132.68
A8: Léane | B8: 6.05 | C8: 0 | D8: 242
A9: Total général | B9: 14.583 | C9: 0 | D9: 565.49

Sheet Camille
A1: Camille CRETAL
A3: Classe | B3: 4ème
A5: N° employeur | B5: Z3856707990000 | E5: Distance domicile-eleve aller/retour | F5: 18
E6: Barème km | F6: =0.636 -> 0.636
A7: Date de début des cours | B7: =DATE(2025,9,11) -> 45911
A8: Date de fin des cours
A10: Prix net de l'heure | B10: 35
A11: Prix brut de l'heure | B11: 44.8
A13: Année | B13: Mois | C13: N° mois | D13: Temps réel | E13: Cumul du temps à reporter | F13: Temps à reporter | G13: Temps rémunéré | H13: Temps déclaré | I13: Paiement effectué | J13: Salaire net | K13: Salaire brut | L13: Nombre de déplacements | M13: Frais de déplacement | N13: Total
A14: 2025 | B14: =B7 -> 45911 | C14: =MONTH(B7) -> 9 | D14: 2.22 | E14: =Tableau271243[[#This Row],[Temps réel]]-INT(Tableau271243[[#This Row],[Temps réel]]) -> 0.22 | F14: =IF(Tableau271243[[#This Row],[Cumul du temps à reporter]]<1,0,1) -> 0 | G14: {=_xlfn.IFS(E14<1,INT(D14),E14>1,INT(D14)+1)} -> 2 | H14: 2 | I14: =Tableau271243[[#This Row],[Temps déclaré]]*$B$10 -> 70 | J14: =Tableau271243[[#This Row],[Temps déclaré]]*$B$10 -> 70 | K14: =Tableau271243[[#This Row],[Temps déclaré]]*$B$11 -> 89.6 | L14: 2 | M14: =$F$5*$F$6*Tableau271243[[#This Row],[Nombre de déplacements]] -> 22.896 | N14: =SUM(Tableau271243[[#This Row],[Paiement effectué]],Tableau271243[[#This Row],[Frais de déplacement]]) -> 92.896
A15: 2025 | B15: =EDATE($B$14,Tableau271243[[#This Row],[N° mois]]-$C$14) -> 45941 | C15: =IF(C14<12,$C14+1,1) -> 10 | D15: 3.57 | E15: =Tableau271243[[#This Row],[Temps réel]]-INT(Tableau271243[[#This Row],[Temps réel]])+E14 -> 0.79 | F15: =IF(Tableau271243[[#This Row],[Cumul du temps à reporter]]<1,0,1) -> 0 | G15: {=_xlfn.IFS(E15<1,INT(D15),E15>1,INT(D15)+1)} -> 3 | H15: 3 | I15: =Tableau271243[[#This Row],[Temps déclaré]]*$B$10 -> 105 | J15: =Tableau271243[[#This Row],[Temps déclaré]]*$B$10 -> 105 | K15: =Tableau271243[[#This Row],[Temps déclaré]]*$B$11 -> 134.4 | L15: 3 | M15: =$F$5*$F$6*Tableau271243[[#This Row],[Nombre de déplacements]] -> 34.344 | N15: =SUM(Tableau271243[[#This Row],[Paiement effectué]],Tableau271243[[#This Row],[Frais de déplacement]]) -> 139.344
A16: 2025 | B16: =EDATE($B$14,Tableau271243[[#This Row],[N° mois]]-$C$14) -> 45972 | C16: =IF(C15<12,$C15+1,1) -> 11 | D16: 5 | E16: =E15 -> 0.79 | F16: =IF(Tableau271243[[#This Row],[Cumul du temps à reporter]]<1,0,1) -> 0 | G16: {=_xlfn.IFS(E16<1,INT(D16),E16>1,INT(D16)+1)} -> 5 | H16: 5 | I16: =Tableau271243[[#This Row],[Temps déclaré]]*$B$10 -> 175 | J16: =Tableau271243[[#This Row],[Temps déclaré]]*$B$10 -> 175 | K16: =Tableau271243[[#This Row],[Temps déclaré]]*$B$11 -> 224 | L16: 3 | M16: =$F$5*$F$6*Tableau271243[[#This Row],[Nombre de déplacements]] -> 34.344 | N16: =SUM(Tableau271243[[#This Row],[Paiement effectué]],Tableau271243[[#This Row],[Frais de déplacement]]) -> 209.344
A17: 2025 | B17: =EDATE($B$14,Tableau271243[[#This Row],[N° mois]]-$C$14) -> 46002 | C17: =IF(C16<12,$C16+1,1) -> 12 | D17: 2 | E17: =E16 -> 0.79 | F17: 1 | G17: 3 | H17: 3 | I17: =Tableau271243[[#This Row],[Temps déclaré]]*$B$10 -> 105 | J17: =Tableau271243[[#This Row],[Temps déclaré]]*$B$10 -> 105 | K17: =Tableau271243[[#This Row],[Temps déclaré]]*$B$11 -> 134.4 | L17: 2 | M17: =$F$5*$F$6*Tableau271243[[#This Row],[Nombre de déplacements]] -> 22.896 | N17: =SUM(Tableau271243[[#This Row],[Paiement effectué]],Tableau271243[[#This Row],[Frais de déplacement]]) -> 127.896
A18: 2025 | B18: =EDATE($B$14,Tableau271243[[#This Row],[N° mois]]-$C$14) -> 45668 | C18: =IF(C17<12,$C17+1,1) -> 1 | E18: =Tableau271243[[#This Row],[Temps réel]]-INT(Tableau271243[[#This Row],[Temps réel]]) -> 0 | F18: =IF(Tableau271243[[#This Row],[Cumul du temps à reporter]]<1,0,1) -> 0 | G18: {=_xlfn.IFS(E18<1,INT(D18),E18>1,INT(D18)+1)} -> 0 | I18: =Tableau271243[[#This Row],[Temps déclaré]]*$B$10 -> 0 | J18: =Tableau271243[[#This Row],[Temps déclaré]]*$B$10 -> 0 | K18: =Tableau271243[[#This Row],[Temps déclaré]]*$B$11 -> 0 | M18: =$F$5*$F$6*Tableau271243[[#This Row],[Nombre de déplacements]] -> 0 | N18: =SUM(Tableau271243[[#This Row],[Paiement effectué]],Tableau271243[[#This Row],[Frais de déplacement]]) -> 0
A19: 2026 | B19: =EDATE($B$14,Tableau271243[[#This Row],[N° mois]]-$C$14) -> 45699 | C19: =IF(C18<12,$C18+1,1) -> 2 | E19: =Tableau271243[[#This Row],[Temps réel]]-INT(Tableau271243[[#This Row],[Temps réel]]) -> 0 | F19: =IF(Tableau271243[[#This Row],[Cumul du temps à reporter]]<1,0,1) -> 0 | G19: {=_xlfn.IFS(E19<1,INT(D19),E19>1,INT(D19)+1)} -> 0 | I19: =Tableau271243[[#This Row],[Temps déclaré]]*$B$10 -> 0 | J19: =Tableau271243[[#This Row],[Temps déclaré]]*$B$10 -> 0 | K19: =Tableau271243[[#This Row],[Temps déclaré]]*$B$11 -> 0 | M19: =$F$5*$F$6*Tableau271243[[#This Row],[Nombre de déplacements]] -> 0 | N19: =SUM(Tableau271243[[#This Row],[Paiement effectué]],Tableau271243[[#This Row],[Frais de déplacement]]) -> 0
A20: 2026 | B20: =EDATE($B$14,Tableau271243[[#This Row],[N° mois]]-$C$14) -> 45727 | C20: =IF(C19<12,$C19+1,1) -> 3 | E20: =Tableau271243[[#This Row],[Temps réel]]-INT(Tableau271243[[#This Row],[Temps réel]]) -> 0 | F20: =IF(Tableau271243[[#This Row],[Cumul du temps à reporter]]<1,0,1) -> 0 | G20: {=_xlfn.IFS(E20<1,INT(D20),E20>1,INT(D20)+1)} -> 0 | I20: =Tableau271243[[#This Row],[Temps déclaré]]*$B$10 -> 0 | J20: =Tableau271243[[#This Row],[Temps déclaré]]*$B$10 -> 0 | K20: =Tableau271243[[#This Row],[Temps déclaré]]*$B$11 -> 0 | M20: =$F$5*$F$6*Tableau271243[[#This Row],[Nombre de déplacements]] -> 0 | N20: =SUM(Tableau271243[[#This Row],[Paiement effectué]],Tableau271243[[#This Row],[Frais de déplacement]]) -> 0
A21: 2026 | B21: =EDATE($B$14,Tableau271243[[#This Row],[N° mois]]-$C$14) -> 45758 | C21: =IF(C20<12,$C20+1,1) -> 4 | E21: =Tableau271243[[#This Row],[Temps réel]]-INT(Tableau271243[[#This Row],[Temps réel]]) -> 0 | F21: =IF(Tableau271243[[#This Row],[Cumul du temps à reporter]]<1,0,1) -> 0 | G21: {=_xlfn.IFS(E21<1,INT(D21),E21>1,INT(D21)+1)} -> 0 | I21: =Tableau271243[[#This Row],[Temps déclaré]]*$B$10 -> 0 | J21: =Tableau271243[[#This Row],[Temps déclaré]]*$B$10 -> 0 | K21: =Tableau271243[[#This Row],[Temps déclaré]]*$B$11 -> 0 | M21: =$F$5*$F$6*Tableau271243[[#This Row],[Nombre de déplacements]] -> 0 | N21: =SUM(Tableau271243[[#This Row],[Paiement effectué]],Tableau271243[[#This Row],[Frais de déplacement]]) -> 0
A22: 2026 | B22: =EDATE($B$14,Tableau271243[[#This Row],[N° mois]]-$C$14) -> 45788 | C22: =IF(C21<12,$C21+1,1) -> 5 | E22: =Tableau271243[[#This Row],[Temps réel]]-INT(Tableau271243[[#This Row],[Temps réel]]) -> 0 | F22: =IF(Tableau271243[[#This Row],[Cumul du temps à reporter]]<1,0,1) -> 0 | G22: {=_xlfn.IFS(E22<1,INT(D22),E22>1,INT(D22)+1)} -> 0 | I22: =Tableau271243[[#This Row],[Temps déclaré]]*$B$10 -> 0 | J22: =Tableau271243[[#This Row],[Temps déclaré]]*$B$10 -> 0 | K22: =Tableau271243[[#This Row],[Temps déclaré]]*$B$11 -> 0 | M22: =$F$5*$F$6*Tableau271243[[#This Row],[Nombre de déplacements]] -> 0 | N22: =SUM(Tableau271243[[#This Row],[Paiement effectué]],Tableau271243[[#This Row],[Frais de déplacement]]) -> 0
A23: 2026 | B23: =EDATE($B$14,Tableau271243[[#This Row],[N° mois]]-$C$14) -> 45819 | C23: =IF(C22<12,$C22+1,1) -> 6 | E23: =Tableau271243[[#This Row],[Temps réel]]-INT(Tableau271243[[#This Row],[Temps réel]]) -> 0 | F23: =IF(Tableau271243[[#This Row],[Cumul du temps à reporter]]<1,0,1) -> 0 | G23: {=_xlfn.IFS(E23<1,INT(D23),E23>1,INT(D23)+1)} -> 0 | I23: =Tableau271243[[#This Row],[Temps déclaré]]*$B$10 -> 0 | J23: =Tableau271243[[#This Row],[Temps déclaré]]*$B$10 -> 0 | K23: =Tableau271243[[#This Row],[Temps déclaré]]*$B$11 -> 0 | M23: =$F$5*$F$6*Tableau271243[[#This Row],[Nombre de déplacements]] -> 0 | N23: =SUM(Tableau271243[[#This Row],[Paiement effectué]],Tableau271243[[#This Row],[Frais de déplacement]]) -> 0
A24: 2026 | B24: =EDATE($B$14,Tableau271243[[#This Row],[N° mois]]-$C$14) -> 45849 | C24: =IF(C23<12,$C23+1,1) -> 7 | E24: =Tableau271243[[#This Row],[Temps réel]]-INT(Tableau271243[[#This Row],[Temps réel]]) -> 0 | F24: =IF(Tableau271243[[#This Row],[Cumul du temps à reporter]]<1,0,1) -> 0 | G24: {=_xlfn.IFS(E24<1,INT(D24),E24>1,INT(D24)+1)} -> 0 | I24: =Tableau271243[[#This Row],[Temps déclaré]]*$B$10 -> 0 | J24: =Tableau271243[[#This Row],[Temps déclaré]]*$B$10 -> 0 | K24: =Tableau271243[[#This Row],[Temps déclaré]]*$B$11 -> 0 | M24: =$F$5*$F$6*Tableau271243[[#This Row],[Nombre de déplacements]] -> 0 | N24: =SUM(Tableau271243[[#This Row],[Paiement effectué]],Tableau271243[[#This Row],[Frais de déplacement]]) -> 0
A25: Total | D25: =SUBTOTAL(109,Tableau271243[Temps réel]) -> 12.79 | G25: =SUBTOTAL(109,Tableau271243[Temps rémunéré]) -> 13 | H25: =SUBTOTAL(109,Tableau271243[Temps déclaré]) -> 13 | I25: =SUBTOTAL(109,Tableau271243[Paiement effectué]) -> 455 | J25: =SUBTOTAL(109,Tableau271243[Salaire net]) -> 455 | K25: =SUBTOTAL(109,Tableau271243[Salaire brut]) -> 582.4 | M25: =SUBTOTAL(109,Tableau271243[Frais de déplacement]) -> 114.48 | N25: =SUBTOTAL(109,Tableau271243[Total]) -> 569.48
A27: Mois à déclarer | B27: 46014
A28: Nombre d'heure à déclarer | B28: 3
A29: Frais de déplacement | B29: =M17 -> 22.896

Sheet Valentine
A1: Valentine PAITREAULT
A3: Classe | B3: 2nde générale
A5: N° employeur | B5: Z3895566290003 | E5: Distance domicile-eleve aller/retour | F5: 20
E6: Barème km | F6: =0.636 -> 0.636
A7: Date de début des cours | B7: 45945
A8: Date de fin des cours
A10: Prix net de l'heure | B10: 40
A11: Prix brut de l'heure | B11: 44.8
A13: Année | B13: Mois | C13: N° mois | D13: Temps réel | E13: Cumul du temps à reporter | F13: Temps à reporter | G13: Temps rémunéré | H13: Temps déclaré | I13: Paiement effectué | J13: Salaire net | K13: Salaire brut | L13: Nombre de déplacements | M13: Frais de déplacement | N13: Total
A14: 2025 | B14: =B7 -> 45945 | C14: =MONTH(B7) -> 10 | D14: 1.65 | E14: =Tableau2712436[[#This Row],[Temps réel]]-INT(Tableau2712436[[#This Row],[Temps réel]]) -> 0.65 | F14: =IF(Tableau2712436[[#This Row],[Cumul du temps à reporter]]<1,0,1) -> 0 | G14: {=_xlfn.IFS(E14<1,INT(D14),E14>1,INT(D14)+1)} -> 1 | H14: 1 | I14: =Tableau2712436[[#This Row],[Temps déclaré]]*$B$10 -> 40 | J14: =Tableau2712436[[#This Row],[Temps déclaré]]*$B$10 -> 40 | K14: =Tableau2712436[[#This Row],[Temps déclaré]]*$B$11 -> 44.8 | L14: 1 | M14: =$F$5*$F$6*Tableau2712436[[#This Row],[Nombre de déplacements]] -> 12.72 | N14: =SUM(Tableau2712436[[#This Row],[Paiement effectué]],Tableau2712436[[#This Row],[Frais de déplacement]]) -> 52.72
A15: 2025 | B15: =EDATE($B$14,Tableau2712436[[#This Row],[N° mois]]-$C$14) -> 45976 | C15: =IF(C14<12,$C14+1,1) -> 11 | D15: 1 | E15: =Tableau2712436[[#This Row],[Temps réel]]-INT(Tableau2712436[[#This Row],[Temps réel]])+E14 -> 0.65 | F15: =IF(Tableau2712436[[#This Row],[Cumul du temps à reporter]]<1,0,1) -> 0 | G15: {=_xlfn.IFS(E15<1,INT(D15),E15>1,INT(D15)+1)} -> 1 | H15: 1 | I15: =Tableau2712436[[#This Row],[Temps déclaré]]*$B$10 -> 40 | J15: =Tableau2712436[[#This Row],[Temps déclaré]]*$B$10 -> 40 | K15: =Tableau2712436[[#This Row],[Temps déclaré]]*$B$11 -> 44.8 | L15: 1 | M15: =$F$5*$F$6*Tableau2712436[[#This Row],[Nombre de déplacements]] -> 12.72 | N15: =SUM(Tableau2712436[[#This Row],[Paiement effectué]],Tableau2712436[[#This Row],[Frais de déplacement]]) -> 52.72
A16: 2025 | B16: =EDATE($B$14,Tableau2712436[[#This Row],[N° mois]]-$C$14) -> 46006 | C16: =IF(C15<12,$C15+1,1) -> 12 | D16: =3+1*12/60 -> 3.2 | E16: =E15+Tableau2712436[[#This Row],[Temps réel]]-INT(Tableau2712436[[#This Row],[Temps réel]]) -> 0.85 | F16: =IF(Tableau2712436[[#This Row],[Cumul du temps à reporter]]<1,0,1) -> 0 | G16: {=_xlfn.IFS(E16<1,INT(D16),E16>1,INT(D16)+1)} -> 3 | H16: 3 | I16: =Tableau2712436[[#This Row],[Temps déclaré]]*$B$10 -> 120 | J16: =Tableau2712436[[#This Row],[Temps déclaré]]*$B$10 -> 120 | K16: =Tableau2712436[[#This Row],[Temps déclaré]]*$B$11 -> 134.4 | L16: 3 | M16: =$F$5*$F$6*Tableau2712436[[#This Row],[Nombre de déplacements]] -> 38.16 | N16: =SUM(Tableau2712436[[#This Row],[Paiement effectué]],Tableau2712436[[#This Row],[Frais de déplacement]]) -> 158.16
A17: 2025 | B17: =EDATE($B$14,Tableau2712436[[#This Row],[N° mois]]-$C$14) -> 45672 | C17: =IF(C16<12,$C16+1,1) -> 1 | E17: =Tableau2712436[[#This Row],[Temps réel]]-INT(Tableau2712436[[#This Row],[Temps réel]]) -> 0 | F17: =IF(Tableau2712436[[#This Row],[Cumul du temps à reporter]]<1,0,1) -> 0 | G17: {=_xlfn.IFS(E17<1,INT(D17),E17>1,INT(D17)+1)} -> 0 | I17: =Tableau2712436[[#This Row],[Temps déclaré]]*$B$10 -> 0 | J17: =Tableau2712436[[#This Row],[Temps déclaré]]*$B$10 -> 0 | K17: =Tableau2712436[[#This Row],[Temps déclaré]]*$B$11 -> 0 | M17: =$F$5*$F$6*Tableau2712436[[#This Row],[Nombre de déplacements]] -> 0 | N17: =SUM(Tableau2712436[[#This Row],[Paiement effectué]],Tableau2712436[[#This Row],[Frais de déplacement]]) -> 0
A18: 2025 | B18: =EDATE($B$14,Tableau2712436[[#This Row],[N° mois]]-$C$14) -> 45703 | C18: =IF(C17<12,$C17+1,1) -> 2 | E18: =Tableau2712436[[#This Row],[Temps réel]]-INT(Tableau2712436[[#This Row],[Temps réel]]) -> 0 | F18: =IF(Tableau2712436[[#This Row],[Cumul du temps à reporter]]<1,0,1) -> 0 | G18: {=_xlfn.IFS(E18<1,INT(D18),E18>1,INT(D18)+1)} -> 0 | I18: =Tableau2712436[[#This Row],[Temps déclaré]]*$B$10 -> 0 | J18: =Tableau2712436[[#This Row],[Temps déclaré]]*$B$10 -> 0 | K18: =Tableau2712436[[#This Row],[Temps déclaré]]*$B$11 -> 0 | M18: =$F$5*$F$6*Tableau2712436[[#This Row],[Nombre de déplacements]] -> 0 | N18: =SUM(Tableau2712436[[#This Row],[Paiement effectué]],Tableau2712436[[#This Row],[Frais de déplacement]]) -> 0
A19: 2026 | B19: =EDATE($B$14,Tableau2712436[[#This Row],[N° mois]]-$C$14) -> 45731 | C19: =IF(C18<12,$C18+1,1) -> 3 | E19: =Tableau2712436[[#This Row],[Temps réel]]-INT(Tableau2712436[[#This Row],[Temps réel]]) -> 0 | F19: =IF(Tableau2712436[[#This Row],[Cumul du temps à reporter]]<1,0,1) -> 0 | G19: {=_xlfn.IFS(E19<1,INT(D19),E19>1,INT(D19)+1)} -> 0 | I19: =Tableau2712436[[#This Row],[Temps déclaré]]*$B$10 -> 0 | J19: =Tableau2712436[[#This Row],[Temps déclaré]]*$B$10 -> 0 | K19: =Tableau2712436[[#This Row],[Temps déclaré]]*$B$11 -> 0 | M19: =$F$5*$F$6*Tableau2712436[[#This Row],[Nombre de déplacements]] -> 0 | N19: =SUM(Tableau2712436[[#This Row],[Paiement effectué]],Tableau2712436[[#This Row],[Frais de déplacement]]) -> 0
A20: 2026 | B20: =EDATE($B$14,Tableau2712436[[#This Row],[N° mois]]-$C$14) -> 45762 | C20: =IF(C19<12,$C19+1,1) -> 4 | E20: =Tableau2712436[[#This Row],[Temps réel]]-INT(Tableau2712436[[#This Row],[Temps réel]]) -> 0 | F20: =IF(Tableau2712436[[#This Row],[Cumul du temps à reporter]]<1,0,1) -> 0 | G20: {=_xlfn.IFS(E20<1,INT(D20),E20>1,INT(D20)+1)} -> 0 | I20: =Tableau2712436[[#This Row],[Temps déclaré]]*$B$10 -> 0 | J20: =Tableau2712436[[#This Row],[Temps déclaré]]*$B$10 -> 0 | K20: =Tableau2712436[[#This Row],[Temps déclaré]]*$B$11 -> 0 | M20: =$F$5*$F$6*Tableau2712436[[#This Row],[Nombre de déplacements]] -> 0 | N20: =SUM(Tableau2712436[[#This Row],[Paiement effectué]],Tableau2712436[[#This Row],[Frais de déplacement]]) -> 0
A21: 2026 | B21: =EDATE($B$14,Tableau2712436[[#This Row],[N° mois]]-$C$14) -> 45792 | C21: =IF(C20<12,$C20+1,1) -> 5 | E21: =Tableau2712436[[#This Row],[Temps réel]]-INT(Tableau2712436[[#This Row],[Temps réel]]) -> 0 | F21: =IF(Tableau2712436[[#This Row],[Cumul du temps à reporter]]<1,0,1) -> 0 | G21: {=_xlfn.IFS(E21<1,INT(D21),E21>1,INT(D21)+1)} -> 0 | I21: =Tableau2712436[[#This Row],[Temps déclaré]]*$B$10 -> 0 | J21: =Tableau2712436[[#This Row],[Temps déclaré]]*$B$10 -> 0 | K21: =Tableau2712436[[#This Row],[Temps déclaré]]*$B$11 -> 0 | M21: =$F$5*$F$6*Tableau2712436[[#This Row],[Nombre de déplacements]] -> 0 | N21: =SUM(Tableau2712436[[#This Row],[Paiement effectué]],Tableau2712436[[#This Row],[Frais de déplacement]]) -> 0
A22: 2026 | B22: =EDATE($B$14,Tableau2712436[[#This Row],[N° mois]]-$C$14) -> 45823 | C22: =IF(C21<12,$C21+1,1) -> 6 | E22: =Tableau2712436[[#This Row],[Temps réel]]-INT(Tableau2712436[[#This Row],[Temps réel]]) -> 0 | F22: =IF(Tableau2712436[[#This Row],[Cumul du temps à reporter]]<1,0,1) -> 0 | G22: {=_xlfn.IFS(E22<1,INT(D22),E22>1,INT(D22)+1)} -> 0 | I22: =Tableau2712436[[#This Row],[Temps déclaré]]*$B$10 -> 0 | J22: =Tableau2712436[[#This Row],[Temps déclaré]]*$B$10 -> 0 | K22: =Tableau2712436[[#This Row],[Temps déclaré]]*$B$11 -> 0 | M22: =$F$5*$F$6*Tableau2712436[[#This Row],[Nombre de déplacements]] -> 0 | N22: =SUM(Tableau2712436[[#This Row],[Paiement effectué]],Tableau2712436[[#This Row],[Frais de déplacement]]) -> 0
A23: 2026 | B23: =EDATE($B$14,Tableau2712436[[#This Row],[N° mois]]-$C$14) -> 45853 | C23: =IF(C22<12,$C22+1,1) -> 7 | E23: =Tableau2712436[[#This Row],[Temps réel]]-INT(Tableau2712436[[#This Row],[Temps réel]]) -> 0 | F23: =IF(Tableau2712436[[#This Row],[Cumul du temps à reporter]]<1,0,1) -> 0 | G23: {=_xlfn.IFS(E23<1,INT(D23),E23>1,INT(D23)+1)} -> 0 | I23: =Tableau2712436[[#This Row],[Temps déclaré]]*$B$10 -> 0 | J23: =Tableau2712436[[#This Row],[Temps déclaré]]*$B$10 -> 0 | K23: =Tableau2712436[[#This Row],[Temps déclaré]]*$B$11 -> 0 | M23: =$F$5*$F$6*Tableau2712436[[#This Row],[Nombre de déplacements]] -> 0 | N23: =SUM(Tableau2712436[[#This Row],[Paiement effectué]],Tableau2712436[[#This Row],[Frais de déplacement]]) -> 0
A24: 2026 | B24: =EDATE($B$14,Tableau2712436[[#This Row],[N° mois]]-$C$14) -> 45884 | C24: =IF(C23<12,$C23+1,1) -> 8 | E24: =Tableau2712436[[#This Row],[Temps réel]]-INT(Tableau2712436[[#This Row],[Temps réel]]) -> 0 | F24: =IF(Tableau2712436[[#This Row],[Cumul du temps à reporter]]<1,0,1) -> 0 | G24: {=_xlfn.IFS(E24<1,INT(D24),E24>1,INT(D24)+1)} -> 0 | I24: =Tableau2712436[[#This Row],[Temps déclaré]]*$B$10 -> 0 | J24: =Tableau2712436[[#This Row],[Temps déclaré]]*$B$10 -> 0 | K24: =Tableau2712436[[#This Row],[Temps déclaré]]*$B$11 -> 0 | M24: =$F$5*$F$6*Tableau2712436[[#This Row],[Nombre de déplacements]] -> 0 | N24: =SUM(Tableau2712436[[#This Row],[Paiement effectué]],Tableau2712436[[#This Row],[Frais de déplacement]]) -> 0
A25: Total | D25: =SUBTOTAL(109,Tableau2712436[Temps réel]) -> 5.85 | G25: =SUBTOTAL(109,Tableau2712436[Temps rémunéré]) -> 5 | H25: =SUBTOTAL(109,Tableau2712436[Temps déclaré]) -> 5 | I25: =SUBTOTAL(109,Tableau2712436[Paiement effectué]) -> 200 | J25: =SUBTOTAL(109,Tableau2712436[Salaire net]) -> 200 | K25: =SUBTOTAL(109,Tableau2712436[Salaire brut]) -> 224 | M25: =SUBTOTAL(109,Tableau2712436[Frais de déplacement]) -> 63.6 | N25: =SUBTOTAL(109,Tableau2712436[Total]) -> 263.6
A27: Mois à déclarer | B27: 46014
A28: Nombre d'heure à déclarer | B28: 3
A29: Frais de déplacement | B29: =+M16 -> 38.16

Sheet Léon
A1: Léon PIETRI
A3: Classe | B3: 2nd bac pro
A5: N° employeur | B5: Z396615259000 | E5: Distance domicile-eleve aller/retour | F5: 26
E6: Barème km | F6: =0.636 -> 0.636
A7: Date de début des cours | B7: =DATE(2025,8,27) -> 45896
A8: Date de fin des cours
A10: Prix net de l'heure | B10: 40
A11: Prix brut de l'heure | B11: =B10*1.28 -> 51.2
A13: Année | B13: Mois | C13: N° mois | D13: Temps réel | E13: Cumul du temps à reporter | F13: Temps à reporter | G13: Temps rémunéré | H13: Temps déclaré | I13: Paiement effectué | J13: Salaire net | K13: Salaire brut | L13: Nombre de déplacements | M13: Frais de déplacement | N13: Total
A14: 2025 | B14: =B7 -> 45896 | C14: =MONTH(B7) -> 8 | D14: 1.48 | E14: =Tableau27124[[#This Row],[Temps réel]]-INT(Tableau27124[[#This Row],[Temps réel]]) -> 0.48 | F14: =IF(Tableau27124[[#This Row],[Cumul du temps à reporter]]<1,0,1) -> 0 | G14: {=_xlfn.IFS(E14<1,INT(D14),E14>1,INT(D14)+1)} -> 1 | H14: 0 | I14: =Tableau27124[[#This Row],[Temps déclaré]]*$B$10 -> 0 | J14: =Tableau27124[[#This Row],[Temps déclaré]]*$B$10 -> 0 | K14: =Tableau27124[[#This Row],[Temps déclaré]]*$B$11 -> 0 | L14: 1 | M14: =$F$5*$F$6*Tableau27124[[#This Row],[Nombre de déplacements]] -> 16.536 | N14: =SUM(Tableau27124[[#This Row],[Paiement effectué]],Tableau27124[[#This Row],[Frais de déplacement]]) -> 16.536
A15: 2025 | B15: =EDATE($B$14,Tableau27124[[#This Row],[N° mois]]-$C$14) -> 45927 | C15: =IF(C14<12,$C14+1,1) -> 9 | D15: =1.08+1.5 -> 2.58 | E15: =Tableau27124[[#This Row],[Temps réel]]-INT(Tableau27124[[#This Row],[Temps réel]])+E14 -> 1.06 | F15: =IF(Tableau27124[[#This Row],[Cumul du temps à reporter]]<1,0,1) -> 1 | G15: {=_xlfn.IFS(E15<1,INT(D15),E15>1,INT(D15)+1)} -> 3 | H15: 4 | I15: =Tableau27124[[#This Row],[Temps déclaré]]*$B$10 -> 160 | J15: =Tableau27124[[#This Row],[Temps déclaré]]*$B$10 -> 160 | K15: =Tableau27124[[#This Row],[Temps déclaré]]*$B$11 -> 204.8 | L15: 2 | M15: =$F$5*$F$6*Tableau27124[[#This Row],[Nombre de déplacements]] -> 33.072 | N15: =SUM(Tableau27124[[#This Row],[Paiement effectué]],Tableau27124[[#This Row],[Frais de déplacement]]) -> 193.072
A16: 2025 | B16: =EDATE($B$14,Tableau27124[[#This Row],[N° mois]]-$C$14) -> 45957 | C16: =IF(C15<12,$C15+1,1) -> 10 | D16: =3.32+1.5 -> 4.82 | E16: =0.06+0.82 -> 0.88 | F16: =IF(Tableau27124[[#This Row],[Cumul du temps à reporter]]<1,0,1) -> 0 | G16: {=_xlfn.IFS(E16<1,INT(D16),E16>1,INT(D16)+1)} -> 4 | H16: 4 | I16: =Tableau27124[[#This Row],[Temps déclaré]]*$B$10 -> 160 | J16: =Tableau27124[[#This Row],[Temps déclaré]]*$B$10 -> 160 | K16: =Tableau27124[[#This Row],[Temps déclaré]]*$B$11 -> 204.8 | L16: 3 | M16: =$F$5*$F$6*Tableau27124[[#This Row],[Nombre de déplacements]] -> 49.608 | N16: =SUM(Tableau27124[[#This Row],[Paiement effectué]],Tableau27124[[#This Row],[Frais de déplacement]]) -> 209.608
A17: 2025 | B17: =EDATE($B$14,Tableau27124[[#This Row],[N° mois]]-$C$14) -> 45988 | C17: =IF(C16<12,$C16+1,1) -> 11 | D17: =3+12/60 -> 3.2 | E17: =E16+0.2 -> 1.08 | F17: =IF(Tableau27124[[#This Row],[Cumul du temps à reporter]]<1,0,1) -> 1 | G17: {=_xlfn.IFS(E17<1,INT(D17),E17>1,INT(D17)+1)} -> 4 | H17: 4 | I17: =Tableau27124[[#This Row],[Temps déclaré]]*$B$10 -> 160 | J17: =Tableau27124[[#This Row],[Temps déclaré]]*$B$10 -> 160 | K17: =Tableau27124[[#This Row],[Temps déclaré]]*$B$11 -> 204.8 | L17: 2 | M17: =$F$5*$F$6*Tableau27124[[#This Row],[Nombre de déplacements]] -> 33.072 | N17: =SUM(Tableau27124[[#This Row],[Paiement effectué]],Tableau27124[[#This Row],[Frais de déplacement]]) -> 193.072
A18: 2025 | B18: =EDATE($B$14,Tableau27124[[#This Row],[N° mois]]-$C$14) -> 46018 | C18: =IF(C17<12,$C17+1,1) -> 12 | D18: =5+14/60 -> 5.2333333 | E18: =Tableau27124[[#This Row],[Temps réel]]-INT(Tableau27124[[#This Row],[Temps réel]])+0.08 -> 0.31333333 | F18: =IF(Tableau27124[[#This Row],[Cumul du temps à reporter]]<1,0,1) -> 0 | G18: {=_xlfn.IFS(E18<1,INT(D18),E18>1,INT(D18)+1)} -> 5 | H18: 5 | I18: =Tableau27124[[#This Row],[Temps déclaré]]*$B$10 -> 200 | J18: =Tableau27124[[#This Row],[Temps déclaré]]*$B$10 -> 200 | K18: =Tableau27124[[#This Row],[Temps déclaré]]*$B$11 -> 256 | L18: 3 | M18: =$F$5*$F$6*Tableau27124[[#This Row],[Nombre de déplacements]] -> 49.608 | N18: =SUM(Tableau27124[[#This Row],[Paiement effectué]],Tableau27124[[#This Row],[Frais de déplacement]]) -> 249.608
A19: 2026 | B19: =EDATE($B$14,Tableau27124[[#This Row],[N° mois]]-$C$14) -> 45684 | C19: =IF(C18<12,$C18+1,1) -> 1 | E19: =Tableau27124[[#This Row],[Temps réel]]-INT(Tableau27124[[#This Row],[Temps réel]]) -> 0 | F19: =IF(Tableau27124[[#This Row],[Cumul du temps à reporter]]<1,0,1) -> 0 | G19: {=_xlfn.IFS(E19<1,INT(D19),E19>1,INT(D19)+1)} -> 0 | I19: =Tableau27124[[#This Row],[Temps déclaré]]*$B$10 -> 0 | J19: =Tableau27124[[#This Row],[Temps déclaré]]*$B$10 -> 0 | K19: =Tableau27124[[#This Row],[Temps déclaré]]*$B$11 -> 0 | M19: =$F$5*$F$6*Tableau27124[[#This Row],[Nombre de déplacements]] -> 0 | N19: =SUM(Tableau27124[[#This Row],[Paiement effectué]],Tableau27124[[#This Row],[Frais de déplacement]]) -> 0
A20: 2026 | B20: =EDATE($B$14,Tableau27124[[#This Row],[N° mois]]-$C$14) -> 45715 | C20: =IF(C19<12,$C19+1,1) -> 2 | E20: =Tableau27124[[#This Row],[Temps réel]]-INT(Tableau27124[[#This Row],[Temps réel]]) -> 0 | F20: =IF(Tableau27124[[#This Row],[Cumul du temps à reporter]]<1,0,1) -> 0 | G20: {=_xlfn.IFS(E20<1,INT(D20),E20>1,INT(D20)+1)} -> 0 | I20: =Tableau27124[[#This Row],[Temps déclaré]]*$B$10 -> 0 | J20: =Tableau27124[[#This Row],[Temps déclaré]]*$B$10 -> 0 | K20: =Tableau27124[[#This Row],[Temps déclaré]]*$B$11 -> 0 | M20: =$F$5*$F$6*Tableau27124[[#This Row],[Nombre de déplacements]] -> 0 | N20: =SUM(Tableau27124[[#This Row],[Paiement effectué]],Tableau27124[[#This Row],[Frais de déplacement]]) -> 0
A21: 2026 | B21: =EDATE($B$14,Tableau27124[[#This Row],[N° mois]]-$C$14) -> 45743 | C21: =IF(C20<12,$C20+1,1) -> 3 | E21: =Tableau27124[[#This Row],[Temps réel]]-INT(Tableau27124[[#This Row],[Temps réel]]) -> 0 | F21: =IF(Tableau27124[[#This Row],[Cumul du temps à reporter]]<1,0,1) -> 0 | G21: {=_xlfn.IFS(E21<1,INT(D21),E21>1,INT(D21)+1)} -> 0 | I21: =Tableau27124[[#This Row],[Temps déclaré]]*$B$10 -> 0 | J21: =Tableau27124[[#This Row],[Temps déclaré]]*$B$10 -> 0 | K21: =Tableau27124[[#This Row],[Temps déclaré]]*$B$11 -> 0 | M21: =$F$5*$F$6*Tableau27124[[#This Row],[Nombre de déplacements]] -> 0 | N21: =SUM(Tableau27124[[#This Row],[Paiement effectué]],Tableau27124[[#This Row],[Frais de déplacement]]) -> 0
A22: 2026 | B22: =EDATE($B$14,Tableau27124[[#This Row],[N° mois]]-$C$14) -> 45774 | C22: =IF(C21<12,$C21+1,1) -> 4 | E22: =Tableau27124[[#This Row],[Temps réel]]-INT(Tableau27124[[#This Row],[Temps réel]]) -> 0 | F22: =IF(Tableau27124[[#This Row],[Cumul du temps à reporter]]<1,0,1) -> 0 | G22: {=_xlfn.IFS(E22<1,INT(D22),E22>1,INT(D22)+1)} -> 0 | I22: =Tableau27124[[#This Row],[Temps déclaré]]*$B$10 -> 0 | J22: =Tableau27124[[#This Row],[Temps déclaré]]*$B$10 -> 0 | K22: =Tableau27124[[#This Row],[Temps déclaré]]*$B$11 -> 0 | M22: =$F$5*$F$6*Tableau27124[[#This Row],[Nombre de déplacements]] -> 0 | N22: =SUM(Tableau27124[[#This Row],[Paiement effectué]],Tableau27124[[#This Row],[Frais de déplacement]]) -> 0
A23: 2026 | B23: =EDATE($B$14,Tableau27124[[#This Row],[N° mois]]-$C$14) -> 45804 | C23: =IF(C22<12,$C22+1,1) -> 5 | E23: =Tableau27124[[#This Row],[Temps réel]]-INT(Tableau27124[[#This Row],[Temps réel]]) -> 0 | F23: =IF(Tableau27124[[#This Row],[Cumul du temps à reporter]]<1,0,1) -> 0 | G23: {=_xlfn.IFS(E23<1,INT(D23),E23>1,INT(D23)+1)} -> 0 | I23: =Tableau27124[[#This Row],[Temps déclaré]]*$B$10 -> 0 | J23: =Tableau27124[[#This Row],[Temps déclaré]]*$B$10 -> 0 | K23: =Tableau27124[[#This Row],[Temps déclaré]]*$B$11 -> 0 | M23: =$F$5*$F$6*Tableau27124[[#This Row],[Nombre de déplacements]] -> 0 | N23: =SUM(Tableau27124[[#This Row],[Paiement effectué]],Tableau27124[[#This Row],[Frais de déplacement]]) -> 0
A24: 2026 | B24: =EDATE($B$14,Tableau27124[[#This Row],[N° mois]]-$C$14) -> 45835 | C24: =IF(C23<12,$C23+1,1) -> 6 | E24: =Tableau27124[[#This Row],[Temps réel]]-INT(Tableau27124[[#This Row],[Temps réel]]) -> 0 | F24: =IF(Tableau27124[[#This Row],[Cumul du temps à reporter]]<1,0,1) -> 0 | G24: {=_xlfn.IFS(E24<1,INT(D24),E24>1,INT(D24)+1)} -> 0 | I24: =Tableau27124[[#This Row],[Temps déclaré]]*$B$10 -> 0 | J24: =Tableau27124[[#This Row],[Temps déclaré]]*$B$10 -> 0 | K24: =Tableau27124[[#This Row],[Temps déclaré]]*$B$11 -> 0 | M24: =$F$5*$F$6*Tableau27124[[#This Row],[Nombre de déplacements]] -> 0 | N24: =SUM(Tableau27124[[#This Row],[Paiement effectué]],Tableau27124[[#This Row],[Frais de déplacement]]) -> 0
A25: 2026 | B25: =EDATE($B$14,Tableau27124[[#This Row],[N° mois]]-$C$14) -> 45865 | C25: =IF(C24<12,$C24+1,1) -> 7 | E25: =Tableau27124[[#This Row],[Temps réel]]-INT(Tableau27124[[#This Row],[Temps réel]]) -> 0 | F25: =IF(Tableau27124[[#This Row],[Cumul du temps à reporter]]<1,0,1) -> 0 | G25: {=_xlfn.IFS(E25<1,INT(D25),E25>1,INT(D25)+1)} -> 0 | I25: =Tableau27124[[#This Row],[Temps déclaré]]*$B$10 -> 0 | J25: =Tableau27124[[#This Row],[Temps déclaré]]*$B$10 -> 0 | K25: =Tableau27124[[#This Row],[Temps déclaré]]*$B$11 -> 0 | M25: =$F$5*$F$6*Tableau27124[[#This Row],[Nombre de déplacements]] -> 0 | N25: =SUM(Tableau27124[[#This Row],[Paiement effectué]],Tableau27124[[#This Row],[Frais de déplacement]]) -> 0
A26: Total | D26: =SUBTOTAL(109,Tableau27124[Temps réel]) -> 17.313333 | G26: =SUBTOTAL(109,Tableau27124[Temps rémunéré]) -> 17 | H26: =SUBTOTAL(109,Tableau27124[Temps déclaré]) -> 17 | I26: =SUBTOTAL(109,Tableau27124[Paiement effectué]) -> 680 | J26: =SUBTOTAL(109,Tableau27124[Salaire net]) -> 680 | K26: =SUBTOTAL(109,Tableau27124[Salaire brut]) -> 870.4 | M26: =SUBTOTAL(109,Tableau27124[Frais de déplacement]) -> 181.896 | N26: =SUBTOTAL(109,Tableau27124[Total]) -> 861.896
A28: Mois à déclarer | B28: 46014
A29: Nombre d'heure à déclarer | B29: =H18 -> 5
A30: Frais de déplacement | B30: =M18 -> 49.608

Sheet Léane
A1: Léane ROBERT
A3: Classe | B3: 2nde générale
A5: N° employeur | E5: Distance domicile-eleve aller/retour | F5: 37
E6: Barème km | F6: =0.636 -> 0.636
A7: Date de début des cours | B7: =DATE(2025,9,17) -> 45917
A8: Date de fin des cours
A10: Prix net de l'heure | B10: 40
A11: Prix brut de l'heure | B11: =B10*1.28 -> 51.2
A13: Année | B13: Mois | C13: N° mois | D13: Temps réel | E13: Cumul du temps à reporter | F13: Temps à reporter | G13: Temps rémunéré | H13: Temps déclaré | I13: Paiement effectué | J13: Salaire net | K13: Salaire brut | L13: Nombre de déplacements | M13: Frais de déplacement | N13: Total
A14: 2025 | B14: =B7 -> 45917 | C14: =MONTH(B7) -> 9 | D14: 2.6 | E14: =Tableau2712435[[#This Row],[Temps réel]]-INT(Tableau2712435[[#This Row],[Temps réel]]) -> 0.6 | F14: =IF(Tableau2712435[[#This Row],[Cumul du temps à reporter]]<1,0,1) -> 0 | G14: {=_xlfn.IFS(E14<1,INT(D14),E14>1,INT(D14)+1)} -> 2 | H14: 2 | I14: =Tableau2712435[[#This Row],[Temps déclaré]]*$B$10 -> 80 | J14: =Tableau2712435[[#This Row],[Temps déclaré]]*$B$10 -> 80 | K14: =Tableau2712435[[#This Row],[Temps déclaré]]*$B$11 -> 102.4 | L14: 2 | M14: =$F$5*$F$6*Tableau2712435[[#This Row],[Nombre de déplacements]] -> 47.064 | N14: =SUM(Tableau2712435[[#This Row],[Paiement effectué]],Tableau2712435[[#This Row],[Frais de déplacement]]) -> 127.064
A15: 2025 | B15: =EDATE($B$14,Tableau2712435[[#This Row],[N° mois]]-$C$14) -> 45947 | C15: =IF(C14<12,$C14+1,1) -> 10 | D15: 6.05 | E15: =Tableau2712435[[#This Row],[Temps réel]]-INT(Tableau2712435[[#This Row],[Temps réel]])+E14 -> 0.65 | F15: =IF(Tableau2712435[[#This Row],[Cumul du temps à reporter]]<1,0,1) -> 0 | G15: {=_xlfn.IFS(E15<1,INT(D15),E15>1,INT(D15)+1)} -> 6 | H15: 6 | I15: =Tableau2712435[[#This Row],[Temps déclaré]]*$B$10 -> 240 | J15: =Tableau2712435[[#This Row],[Temps déclaré]]*$B$10 -> 240 | K15: =Tableau2712435[[#This Row],[Temps déclaré]]*$B$11 -> 307.2 | L15: 4 | M15: =$F$5*$F$6*Tableau2712435[[#This Row],[Nombre de déplacements]] -> 94.128 | N15: =SUM(Tableau2712435[[#This Row],[Paiement effectué]],Tableau2712435[[#This Row],[Frais de déplacement]]) -> 334.128
A16: 2025 | B16: =EDATE($B$14,Tableau2712435[[#This Row],[N° mois]]-$C$14) -> 45978 | C16: =IF(C15<12,$C15+1,1) -> 11 | D16: =4+10/60 -> 4.1666667 | E16: =E15+0.167 -> 0.817 | F16: =IF(Tableau2712435[[#This Row],[Cumul du temps à reporter]]<1,0,1) -> 0 | G16: {=_xlfn.IFS(E16<1,INT(D16),E16>1,INT(D16)+1)} -> 4 | H16: 4 | I16: =Tableau2712435[[#This Row],[Temps déclaré]]*$B$10 -> 160 | J16: =Tableau2712435[[#This Row],[Temps déclaré]]*$B$10 -> 160 | K16: =Tableau2712435[[#This Row],[Temps déclaré]]*$B$11 -> 204.8 | L16: 3 | M16: =$F$5*$F$6*Tableau2712435[[#This Row],[Nombre de déplacements]] -> 70.596 | N16: =SUM(Tableau2712435[[#This Row],[Paiement effectué]],Tableau2712435[[#This Row],[Frais de déplacement]]) -> 230.596
A17: 2025 | B17: =EDATE($B$14,Tableau2712435[[#This Row],[N° mois]]-$C$14) -> 46008 | C17: =IF(C16<12,$C16+1,1) -> 12 | D17: =2+42/60 -> 2.7 | E17: =Tableau2712435[[#This Row],[Temps réel]]-INT(Tableau2712435[[#This Row],[Temps réel]])+E16 -> 1.517 | F17: =IF(Tableau2712435[[#This Row],[Cumul du temps à reporter]]<1,0,1) -> 1 | G17: {=_xlfn.IFS(E17<1,INT(D17),E17>1,INT(D17)+1)} -> 3 | H17: 4 | I17: =Tableau2712435[[#This Row],[Temps déclaré]]*$B$10 -> 160 | J17: =Tableau2712435[[#This Row],[Temps déclaré]]*$B$10 -> 160 | K17: =Tableau2712435[[#This Row],[Temps déclaré]]*$B$11 -> 204.8 | L17: 3 | M17: =$F$5*$F$6*Tableau2712435[[#This Row],[Nombre de déplacements]] -> 70.596 | N17: =SUM(Tableau2712435[[#This Row],[Paiement effectué]],Tableau2712435[[#This Row],[Frais de déplacement]]) -> 230.596
A18: 2025 | B18: =EDATE($B$14,Tableau2712435[[#This Row],[N° mois]]-$C$14) -> 45674 | C18: =IF(C17<12,$C17+1,1) -> 1 | E18: =Tableau2712435[[#This Row],[Temps réel]]-INT(Tableau2712435[[#This Row],[Temps réel]])+0.517 -> 0.517 | F18: =IF(Tableau2712435[[#This Row],[Cumul du temps à reporter]]<1,0,1) -> 0 | G18: {=_xlfn.IFS(E18<1,INT(D18),E18>1,INT(D18)+1)} -> 0 | I18: =Tableau2712435[[#This Row],[Temps déclaré]]*$B$10 -> 0 | J18: =Tableau2712435[[#This Row],[Temps déclaré]]*$B$10 -> 0 | K18: =Tableau2712435[[#This Row],[Temps déclaré]]*$B$11 -> 0 | M18: =$F$5*$F$6*Tableau2712435[[#This Row],[Nombre de déplacements]] -> 0 | N18: =SUM(Tableau2712435[[#This Row],[Paiement effectué]],Tableau2712435[[#This Row],[Frais de déplacement]]) -> 0
A19: 2026 | B19: =EDATE($B$14,Tableau2712435[[#This Row],[N° mois]]-$C$14) -> 45705 | C19: =IF(C18<12,$C18+1,1) -> 2 | E19: =Tableau2712435[[#This Row],[Temps réel]]-INT(Tableau2712435[[#This Row],[Temps réel]]) -> 0 | F19: =IF(Tableau2712435[[#This Row],[Cumul du temps à reporter]]<1,0,1) -> 0 | G19: {=_xlfn.IFS(E19<1,INT(D19),E19>1,INT(D19)+1)} -> 0 | I19: =Tableau2712435[[#This Row],[Temps déclaré]]*$B$10 -> 0 | J19: =Tableau2712435[[#This Row],[Temps déclaré]]*$B$10 -> 0 | K19: =Tableau2712435[[#This Row],[Temps déclaré]]*$B$11 -> 0 | M19: =$F$5*$F$6*Tableau2712435[[#This Row],[Nombre de déplacements]] -> 0 | N19: =SUM(Tableau2712435[[#This Row],[Paiement effectué]],Tableau2712435[[#This Row],[Frais de déplacement]]) -> 0
A20: 2026 | B20: =EDATE($B$14,Tableau2712435[[#This Row],[N° mois]]-$C$14) -> 45733 | C20: =IF(C19<12,$C19+1,1) -> 3 | E20: =Tableau2712435[[#This Row],[Temps réel]]-INT(Tableau2712435[[#This Row],[Temps réel]]) -> 0 | F20: =IF(Tableau2712435[[#This Row],[Cumul du temps à reporter]]<1,0,1) -> 0 | G20: {=_xlfn.IFS(E20<1,INT(D20),E20>1,INT(D20)+1)} -> 0 | I20: =Tableau2712435[[#This Row],[Temps déclaré]]*$B$10 -> 0 | J20: =Tableau2712435[[#This Row],[Temps déclaré]]*$B$10 -> 0 | K20: =Tableau2712435[[#This Row],[Temps déclaré]]*$B$11 -> 0 | M20: =$F$5*$F$6*Tableau2712435[[#This Row],[Nombre de déplacements]] -> 0 | N20: =SUM(Tableau2712435[[#This Row],[Paiement effectué]],Tableau2712435[[#This Row],[Frais de déplacement]]) -> 0
A21: 2026 | B21: =EDATE($B$14,Tableau2712435[[#This Row],[N° mois]]-$C$14) -> 45764 | C21: =IF(C20<12,$C20+1,1) -> 4 | E21: =Tableau2712435[[#This Row],[Temps réel]]-INT(Tableau2712435[[#This Row],[Temps réel]]) -> 0 | F21: =IF(Tableau2712435[[#This Row],[Cumul du temps à reporter]]<1,0,1) -> 0 | G21: {=_xlfn.IFS(E21<1,INT(D21),E21>1,INT(D21)+1)} -> 0 | I21: =Tableau2712435[[#This Row],[Temps déclaré]]*$B$10 -> 0 | J21: =Tableau2712435[[#This Row],[Temps déclaré]]*$B$10 -> 0 | K21: =Tableau2712435[[#This Row],[Temps déclaré]]*$B$11 -> 0 | M21: =$F$5*$F$6*Tableau2712435[[#This Row],[Nombre de déplacements]] -> 0 | N21: =SUM(Tableau2712435[[#This Row],[Paiement effectué]],Tableau2712435[[#This Row],[Frais de déplacement]]) -> 0
A22: 2026 | B22: =EDATE($B$14,Tableau2712435[[#This Row],[N° mois]]-$C$14) -> 45794 | C22: =IF(C21<12,$C21+1,1) -> 5 | E22: =Tableau2712435[[#This Row],[Temps réel]]-INT(Tableau2712435[[#This Row],[Temps réel]]) -> 0 | F22: =IF(Tableau2712435[[#This Row],[Cumul du temps à reporter]]<1,0,1) -> 0 | G22: {=_xlfn.IFS(E22<1,INT(D22),E22>1,INT(D22)+1)} -> 0 | I22: =Tableau2712435[[#This Row],[Temps déclaré]]*$B$10 -> 0 | J22: =Tableau2712435[[#This Row],[Temps déclaré]]*$B$10 -> 0 | K22: =Tableau2712435[[#This Row],[Temps déclaré]]*$B$11 -> 0 | M22: =$F$5*$F$6*Tableau2712435[[#This Row],[Nombre de déplacements]] -> 0 | N22: =SUM(Tableau2712435[[#This Row],[Paiement effectué]],Tableau2712435[[#This Row],[Frais de déplacement]]) -> 0
A23: 2026 | B23: =EDATE($B$14,Tableau2712435[[#This Row],[N° mois]]-$C$14) -> 45825 | C23: =IF(C22<12,$C22+1,1) -> 6 | E23: =Tableau2712435[[#This Row],[Temps réel]]-INT(Tableau2712435[[#This Row],[Temps réel]]) -> 0 | F23: =IF(Tableau2712435[[#This Row],[Cumul du temps à reporter]]<1,0,1) -> 0 | G23: {=_xlfn.IFS(E23<1,INT(D23),E23>1,INT(D23)+1)} -> 0 | I23: =Tableau2712435[[#This Row],[Temps déclaré]]*$B$10 -> 0 | J23: =Tableau2712435[[#This Row],[Temps déclaré]]*$B$10 -> 0 | K23: =Tableau2712435[[#This Row],[Temps déclaré]]*$B$11 -> 0 | M23: =$F$5*$F$6*Tableau2712435[[#This Row],[Nombre de déplacements]] -> 0 | N23: =SUM(Tableau2712435[[#This Row],[Paiement effectué]],Tableau2712435[[#This Row],[Frais de déplacement]]) -> 0
A24: 2026 | B24: =EDATE($B$14,Tableau2712435[[#This Row],[N° mois]]-$C$14) -> 45855 | C24: =IF(C23<12,$C23+1,1) -> 7 | E24: =Tableau2712435[[#This Row],[Temps réel]]-INT(Tableau2712435[[#This Row],[Temps réel]]) -> 0 | F24: =IF(Tableau2712435[[#This Row],[Cumul du temps à reporter]]<1,0,1) -> 0 | G24: {=_xlfn.IFS(E24<1,INT(D24),E24>1,INT(D24)+1)} -> 0 | I24: =Tableau2712435[[#This Row],[Temps déclaré]]*$B$10 -> 0 | J24: =Tableau2712435[[#This Row],[Temps déclaré]]*$B$10 -> 0 | K24: =Tableau2712435[[#This Row],[Temps déclaré]]*$B$11 -> 0 | M24: =$F$5*$F$6*Tableau2712435[[#This Row],[Nombre de déplacements]] -> 0 | N24: =SUM(Tableau2712435[[#This Row],[Paiement effectué]],Tableau2712435[[#This Row],[Frais de déplacement]]) -> 0
A25: Total | D25: =SUBTOTAL(109,Tableau2712435[Temps réel]) -> 15.516667 | G25: =SUBTOTAL(109,Tableau2712435[Temps rémunéré]) -> 15 | H25: =SUBTOTAL(109,Tableau2712435[Temps déclaré]) -> 16 | I25: =SUBTOTAL(109,Tableau2712435[Paiement effectué]) -> 640 | J25: =SUBTOTAL(109,Tableau2712435[Salaire net]) -> 640 | K25: =SUBTOTAL(109,Tableau2712435[Salaire brut]) -> 819.2 | M25: =SUBTOTAL(109,Tableau2712435[Frais de déplacement]) -> 282.384 | N25: =SUBTOTAL(109,Tableau2712435[Total]) -> 922.384
A27: Mois à déclarer | B27: 46014
A28: Nombre d'heure à déclarer | B28: =H17 -> 4
A29: Frais de déplacement | B29: =M17 -> 70.596

Sheet Recap
A1: Mois à déclarer | B1: 45953
A3: Eleve | B3: N° employeur | C3: Heures déclarées | D3: Salaire brut | E3: Salaire net | F3: Bulletin de salaire
A4: Camille | B4: =Camille!B5 -> Z3856707990000 | C4: =Camille!B28 -> 3 | D4: =Camille!K17 -> 134.4 | E4: =Camille!J17 -> 105
A5: Valentine | B5: =Valentine!B5 -> Z3895566290003 | C5: =Valentine!B28 -> 3 | D5: =Valentine!K16 -> 134.4 | E5: =Valentine!J16 -> 120 | G5: En attente nov bulletin
A6: Léon | B6: Z396615259000 | C6: =Léon!B29 -> 5 | D6: =Léon!K18 -> 256 | E6: =Léon!J18 -> 200
A7: Léane | B7: Z3922090090004 | C7: =Léane!B28 -> 4 | D7: =Léane!K17 -> 204.8 | E7: =Léane!J17 -> 160
A8: Total | C8: =SUBTOTAL(109,Tableau12[Heures déclarées]) -> 15 | D8: =SUBTOTAL(109,Tableau12[Salaire brut]) -> 729.6 | E8: =SUBTOTAL(109,Tableau12[Salaire net]) -> 585

Sheet Envoi des docs
A1: Prénom | B1: Mail | C1: Document
A2: Darany & Antoine | B2: famillecretal@gmail.com | C2: https://arythmeethic-my.sharepoint.com/personal/florence_louazel_arythmeethic_onmicrosoft_com/Documents/Documents/2025-2026/CESU/Antoine%20CRETAL%20-%20Camille/Temps_Novembre_25_Camille.pdf
A3: Alban | B3: apaitreault@aol.com | C3: https://arythmeethic-my.sharepoint.com/personal/florence_louazel_arythmeethic_onmicrosoft_com/Documents/Documents/2025-2026/CESU/Alban%20PAITREAULT%20-%20Valentine/Temps_nov_25_Valentine.pdf
A4: Sophie | B4: spapotti@gmail.com | C4: https://arythmeethic-my.sharepoint.com/personal/florence_louazel_arythmeethic_onmicrosoft_com/Documents/Documents/2025-2026/CESU/Sophie%20PAPOTI%20-%20Léon/Temps_nov_25_Leon.pdf
A5: Coralie | B5: coralierobert044@gmail.com | C5: https://arythmeethic-my.sharepoint.com/personal/florence_louazel_arythmeethic_onmicrosoft_com/Documents/Documents/2025-2026/CESU/Coralie%20ROBERT%20-%20Léane/Temps_nov_25_Leane.pdf

Sheet Feuil2
A1: Prénom | B1: Mail | C1: Document
A2: Darany & Antoine | B2: florence.louazel@ARythmeEthic.onmicrosoft.com | C2: https://arythmeethic-my.sharepoint.com/personal/florence_louazel_arythmeethic_onmicrosoft_com/Documents/Documents/2025-2026/CESU/Antoine%20CRETAL%20-%20Camille/Temps_Novembre_25_Camille.pdf
